<?xml version="1.0"?>

<robot name="tortoisebot">



  <link name="base_link">

    <visual>

      <geometry>

        <box size="0.6 0.3 0.3"/>

      </geometry>

      <material name="silver">

        <color rgba="0.75 0.75 0.75 1"/>

      </material>

    </visual>

    <collision>

      <geometry>

        <box size="0.6 0.3 0.3"/>

      </geometry>

    </collision>

    <inertial>

      <mass value="1.0"/>

      <inertia ixx="0.015" iyy="0.0375" izz="0.0375" ixy="0" ixz="0" iyz="0"/>

    </inertial>

  </link>



  <link name="front_caster">

    <visual>

      <geometry>

        <box size="0.1 0.1 0.3"/>

      </geometry>

      <material name="silver">

        <color rgba="0.75 0.75 0.75 1"/>

      </material>

    </visual>

    <collision>

      <geometry>

        <box size="0.1 0.1 0.3"/>

      </geometry>

    </collision>

    <inertial>

      <mass value="0.1"/>

      <inertia ixx="0.00083" iyy="0.00083" izz="0.000167" ixy="0" ixz="0" iyz="0"/>

    </inertial>

  </link>



  <link name ="base_footprint">

  </link>



    <joint name="base_footprint_joint" type="fixed">

      <parent link="base_link"/>

      <child link="base_footprint"/>

      <origin rpy="0 0 0" xyz="0 0 -0.1"/>

    </joint>





  <joint name="front_caster_joint" type="continuous">

    <axis xyz="0 0 1"/>

    <parent link="base_link"/>

    <child link="front_caster"/>

    <origin rpy="0 0 0" xyz="0.3 0 0"/>

  </joint>



  <link name="front_wheel">

    <visual>

      <geometry>

        <cylinder length="0.05" radius="0.035"/>

      </geometry>

      <material name="black">

        <color rgba="0 0 0 1"/>

      </material>

    </visual>

    <collision>

      <geometry>

        <cylinder length="0.05" radius="0.035"/>

      </geometry>

    </collision>

    <inertial>

      <mass value="0.1"/>

      <inertia ixx="5.1458e-5" iyy="5.1458e-5" izz="6.125e-5" ixy="0" ixz="0" iyz="0"/>

    </inertial>

  </link>



  <joint name="front_wheel_joint" type="continuous">

    <axis xyz="0 0 1"/>

    <parent link="front_caster"/>

    <child link="front_wheel"/>

    <origin rpy="-1.5708 0 0" xyz="0.05 0 -.15"/>

  </joint>



  <link name="right_wheel">

    <visual>

      <geometry>

        <cylinder length="0.05" radius="0.035"/>

      </geometry>

      <material name="black">

        <color rgba="0 0 0 1"/>

      </material>

    </visual>

    <collision>

      <geometry>

        <cylinder length="0.05" radius="0.035"/>

      </geometry>

    </collision>

    <inertial>

      <mass value="0.1"/>

      <inertia ixx="5.1458e-5" iyy="5.1458e-5" izz="6.125e-5" ixy="0" ixz="0" iyz="0"/>

    </inertial>

  </link>



  <joint name="right_wheel_joint" type="continuous">

    <axis xyz="0 0 1"/>

    <parent link="base_link"/>

    <child link="right_wheel"/>

    <origin rpy="-1.5708 0 0" xyz="-0.2825 -0.125 -.15"/>

  </joint>



  <link name="left_wheel">

    <visual>

      <geometry>

        <cylinder length="0.05" radius="0.035"/>

      </geometry>

      <material name="black">

        <color rgba="0 0 0 1"/>

      </material>

    </visual>

    <collision>

      <geometry>

        <cylinder length="0.05" radius="0.035"/>

      </geometry>

    </collision>

    <inertial>

      <mass value="0.1"/>

      <inertia ixx="5.1458e-5" iyy="5.1458e-5" izz="6.125e-5" ixy="0" ixz="0" iyz="0"/>

    </inertial>

  </link>



  <joint name="left_wheel_joint" type="continuous">

    <axis xyz="0 0 1"/>zz

    <parent link="base_link"/>

    <child link="left_wheel"/>

    <origin rpy="-1.5708 0 0" xyz="-0.2825 0.125 -.15"/>

  </joint>



  <link name="lidar_link">

    <visual>

      <geometry>

        <cylinder radius="0.05" length="0.02"/>

      </geometry>

    </visual>

  </link>

  <link name="camera_link">
      <visual>
        <geometry>
          <cylinder radius="0.05" length="0.02"/>
        </geometry>
        <material name="red">
          <color rgba="0 0 0 1"/>
      </material>
    </visual>
  </link>

  <joint name="camera_link_joint" type="fixed">
    <parent link="base_link"/>
    <child link="camera_link"/>
    <origin xyz="0 0.2 0.2" rpy="0 0 0"/>
  </joint>


  <joint name="lidar_joint" type="fixed">

    <parent link="base_link"/>

    <child link="lidar_link"/>

    <origin xyz="0 0 0.2" rpy="0 0 0"/>

  </joint>

<!-- 

  <gazebo>

    <plugin

      filename="gz-sim-diff-drive-system"

      name="gz::sim::systems::DiffDrive">

      <left_joint>left_wheel_joint</left_joint>

      <right_joint>right_wheel_joint</right_joint>

      <topic>cmd_vel</topic>

      <wheel_separation>0.25</wheel_separation> 

      <wheel_radius>0.035</wheel_radius>

      <max_linear_speed>1.0</max_linear_speed>

      <max_angular_speed>2.0</max_angular_speed>



      <odom_topic>odom</odom_topic>

      <frame_id>odom</frame_id>

      <base_frame>base_link</base_frame>

      <publish_odom>true</publish_odom>

      <publish_tf>true</publish_tf>

    </plugin>



  </gazebo> -->



<gazebo>

  <plugin filename="gz-sim-diff-drive-system" name="gz::sim::systems::DiffDrive">

    <left_joint>left_wheel_joint</left_joint>

    <right_joint>right_wheel_joint</right_joint>

    <wheel_separation>0.25</wheel_separation>

    <wheel_radius>0.035</wheel_radius>

    <frame_id>/odom</frame_id>

    <!-- <odom_topic>odom1</odom_topic> -->

    <child_frame_id>base_link</child_frame_id>

    <robotBaseFrame>base_link</robotBaseFrame> 

    <topic>cmd_vel</topic>

    <tf_topic>tf</tf_topic>

    <publish_tf>true</publish_tf>

    <!-- <publish_odom>true</publish_odom> -->

    <publishWheelJointState>true</publishWheelJointState>

  </plugin>

</gazebo>



<!-- <gazebo reference="lidar_link">

  <sensor name="gpu_lidar" type="gpu_lidar">

    <pose relative_to="lidar_link">0 0 0 0 0 0</pose>

    <gz_frame_id>lidar_link<gz_frame_id>

    <topic>scan</topic>

    <update_rate>10</update_rate>

    <ray>

      <scan>

        <horizontal>

          <samples>360</samples>

          <resolution>1</resolution>

          <min_angle>-3.1416</min_angle>

          <max_angle>3.1416</max_angle>

        </horizontal>

      </scan>

      <noise>

        <type>gaussian</type>

        <mean>0.0</mean>

        <stddev>0.005</stddev>

      </noise>

      <range>

        <min>0.08</min>

        <max>10.0</max>

        <resolution>0.01</resolution>

      </range>

    </ray>

    <always_on>1</always_on>

    <visualize>true</visualize>



    <plugin

      filename="gz-sim-sensors-system"

      name="gz::sim::systems::Sensors">

      <render_engine>ogre2</render_engine>

     

    </plugin>

  

      </sensor>
f'{GZ_SENSOR_PATH}/camera_info@sensor_msgs/msg/CameraInfo@gz.msgs.CameraInfo',
            f'{GZ_SENSOR_PATH
</gazebo> -->



  <gazebo>
    <plugin
    filename="gz-sim-joint-state-publisher-system"
    name="gz::sim::systems::JointStatePublisher">
    <topic>joint_states</topic>
    <joint_name>left_wheel_joint</joint_name>
    <joint_name>right_wheel_joint</joint_name>
    <joint_name>front_caster_joint</joint_name>
    <joint_name>front_wheel_joint</joint_name>

    </plugin>
  </gazebo>



  <gazebo reference="lidar_link">

    <sensor name="gpu_lidar" type="gpu_lidar">

    <pose relative_to='lidar_link'>0 0 0 0 0 0</pose>

    <gz_frame_id>lidar_link</gz_frame_id>

    <topic>scan</topic>

    <update_rate>10</update_rate>

    <ray>

    <scan>

      <horizontal>

        <samples>640</samples>

        <resolution>1</resolution>

        <min_angle>-3.14</min_angle>

        <max_angle>3.14</max_angle>

      </horizontal>

    </scan>

    <range>

    <min>0.08</min>

    <max>10.0</max>

    <resolution>0.01</resolution>

    </range>

    <noise type="gaussian">

    <mean>0.0</mean> <!-- Center of noise -->

    <stddev>0.02</stddev> <!-- Strength of noise (higher = more spikes) -->

    </noise>

    </ray>

    <always_on>1</always_on>

    <visualize>true</visualize>

    <!-- <plugin

    filename="gz-sim-sensors-system"

    name="gz::sim::systems::Sensors">

    <render_engine>ogre2</render_engine>

    </plugin> -->

    </sensor>

  </gazebo>

  <gazebo reference="camera_link">
    <sensor name="depth" type="rgbd_camera">
      <pose>0.122 0 0.257 0 0.46 0</pose>
      <always_on>1</always_on>
      <update_rate>30</update_rate>
      <topic>camera</topic>
      <gz_frame_id>camera_link</gz_frame_id>
      <camera name="depth">
        <horizontal_fov>1.50098</horizontal_fov>
        
        <lens>
          <intrinsics>
            <fx>343.159</fx>
            <fy>343.159</fy>
            <cx>319.5</cx>
            <cy>179.5</cy>
            <s>0</s>
          </intrinsics>
        </lens>

        <distortion>
          <k1>0.0</k1>
          <k2>0.0</k2>
          <k3>0.0</k3>
          <p1>0.0</p1>
          <p2>0.0</p2>
          <center>0.5 0.5</center>
        </distortion>

        <image>
          <width>640</width>
          <height>360</height>
          <format>R8G8B8</format>
        </image>

        <clip>
          <near>0.01</near>
          <far>300</far>
        </clip>

        <depth_camera>
          <clip>
            <near>0.1</near>
            <far>10</far>
          </clip>
        </depth_camera>

        <noise>
          <type>gaussian</type>
          <mean>0</mean>
          <stddev>0.007</stddev>
        </noise>
      </camera>

    </sensor>
  </gazebo>

 


</robot>
